<?xml version="1.0"?>

<robot name="robot_body"  xmlns:xacro="http://www.ros.org/wiki/xacro">

  <!-- Import all Gazebo-customization elements, including Gazebo colors -->
  <xacro:include filename="$(find body_description)/urdf/body.gazebo" />
  <!-- Import Rviz colors -->
  <xacro:include filename="$(find body_description)/urdf/materials.xacro" />

  <xacro:property name="wheelradius" value="0.05" />
  <xacro:property name="damping" value="0.7" />
  <xacro:property name="wheelmass" value="5" />
  <xacro:property name="wheelmoment" value="1" />
  
  
  <link name="base_link">
    <visual>
      <geometry>
        <box size="0.6 0.4 0.4"/>
      </geometry>
      <material name="blue"/>
    </visual>
    <collision>
      <geometry>
        <box size="0.6 0.4 0.4"/>
      </geometry>
    </collision>
    <inertial>
      <mass value="5"/>
      <inertia ixx="0.2" ixy="0.0" ixz="0.0" iyy="0.2" iyz="0.0" izz="0.2"/>
    </inertial>
  </link>

  <link name="right_front_wheel">
    <visual>
      <geometry>
        <cylinder length=".1" radius="${wheelradius}"/>
      </geometry>
      <material name="orange"/>
    </visual>
    <collision>
      <geometry>
        <cylinder length=".1" radius="${wheelradius}"/>
      </geometry>
    </collision>
    <inertial>
      <mass value="${wheelmass}"/>
      <inertia ixx="${wheelmoment}" ixy="0.0" ixz="0.0" iyy="${wheelmoment}" iyz="0.0" izz="${wheelmoment}"/>
    </inertial>
  </link>

  <joint name="right_front_wheel_joint" type="continuous">
    <axis xyz="0 0 -1"/>
    <parent link="base_link"/>
    <child link="right_front_wheel"/>
    <origin rpy="0 1.57075 0" xyz="0.2 0.15 -0.25"/>
    <limit effort="100" velocity="100"/>
    <joint_properties damping="10.0" friction="0.0"/>
    <dynamics damping="${damping}"/>
  </joint>

  <link name="right_back_wheel">
    <visual>
      <geometry>
        <cylinder length=".1" radius="${wheelradius}"/>
      </geometry>
      <material name="black"/>
    </visual>
    <collision>
      <geometry>
        <cylinder length=".1" radius="${wheelradius}"/>
      </geometry>
    </collision>
    <inertial>
      <mass value="${wheelmass}"/>
      <inertia ixx="${wheelmoment}" ixy="0.0" ixz="0.0" iyy="${wheelmoment}" iyz="0.0" izz="${wheelmoment}"/>
    </inertial>
  </link>

  <joint name="right_back_wheel_joint" type="continuous">
    <axis xyz="0 0 1"/>
    <parent link="base_link"/>
    <child link="right_back_wheel"/>
    <origin rpy="0 1.57075 0" xyz="0.2 -0.15 -0.25"/>
    <limit effort="100" velocity="100"/>
    <joint_properties damping="10" friction="0.0"/>
    <dynamics damping="10"/>
  </joint>

  <link name="left_front_wheel">
    <visual>
      <geometry>
        <cylinder length=".1" radius="${wheelradius}"/>
      </geometry>
      <material name="orange"/>
    </visual>
    <collision>
      <geometry>
        <cylinder length=".1" radius="${wheelradius}"/>
      </geometry>
    </collision>
    <inertial>
      <mass value="${wheelmass}"/>
      <inertia ixx="${wheelmoment}" ixy="0.0" ixz="0.0" iyy="${wheelmoment}" iyz="0.0" izz="${wheelmoment}"/>
    </inertial>
  </link>

  <joint name="left_front_wheel_joint" type="continuous">
    <axis xyz="0 0 -1"/>
    <parent link="base_link"/>
    <child link="left_front_wheel"/>
    <origin rpy="0 1.57075 0" xyz="-0.2 0.15 -0.25"/>
    <limit effort="100" velocity="100"/>
    <joint_properties damping="10.0" friction="0.0"/>
    <dynamics damping="${damping}"/>
  </joint>

  <link name="left_back_wheel">
    <visual>
      <geometry>
        <cylinder length=".1" radius="${wheelradius}"/>
      </geometry>
      <material name="black"/>
    </visual>
    <collision>
      <geometry>
        <cylinder length=".1" radius="${wheelradius}"/>
      </geometry>
    </collision>
    <inertial>
      <mass value="${wheelmass}"/>
      <inertia ixx="${wheelmoment}" ixy="0.0" ixz="0.0" iyy="${wheelmoment}" iyz="0.0" izz="${wheelmoment}"/>
    </inertial>
  </link>

  <joint name="left_back_wheel_joint" type="continuous">
    <axis xyz="0 0 1"/>
    <parent link="base_link"/>
    <child link="left_back_wheel"/>
    <origin rpy="0 1.57075 0" xyz="-0.2 -0.15 -0.25"/>
    <limit effort="100" velocity="100"/>
    <joint_properties damping="10" friction="0.0"/>
    <dynamics damping="10"/>
  </joint>

  <link name="neck">
    <visual>
      <geometry>
        <cylinder length="0.8" radius="0.06"/>
      </geometry>
      <material name="blue"/>
    </visual>
    <collision>
      <geometry>
        <box size="0.06 0.06 0.8"/>
      </geometry>
    </collision>
    <inertial>
      <mass value="0.1"/>
      <inertia ixx="0.1" ixy="0.0" ixz="0.0" iyy="0.1" iyz="0.0" izz="0.1"/>
    </inertial>
  </link>

  <joint name="baselink_neck" type="continuous">
    <parent link="base_link"/>
    <child link="neck"/>
    <axis xyz="0 0 1"/>
    <origin xyz="0 0 0.6"/>
    <dynamics damping="${damping}"/>
  </joint>

  <link name="head">
    <visual>
      <geometry>
        <sphere radius="0.2"/>
      </geometry>
      <material name="orange"/>
    </visual>
    <collision>
      <geometry>
        <box size="0.1 0.1 0.1"/>
      </geometry>
    </collision>
    <inertial>
      <mass value="1e-5"/>
      <inertia ixx="0.1" ixy="0.0" ixz="0.0" iyy="0" iyz="0.0" izz="0"/>
    </inertial>
  </link>

  <joint name="neck_head" type="continuous">
    <parent link="neck"/>
    <child link="head"/>
    <axis xyz="1 0 0"/>
    <origin xyz="0 0 0.4"/>
    <dynamics damping="${damping}"/>
  </joint>

  <!-- Camera -->
  <link name="camera_link">
    <collision>
      <origin xyz="0 0 0" rpy="0 0 0"/>
      <geometry>
	       <box size="0.05 0.05 0.05"/>
      </geometry>
    </collision>

    <visual>
      <origin xyz="0 0 0" rpy="0 0 0"/>
      <geometry>
	       <box size="0.05 0.05 0.05"/>
      </geometry>
      <material name="red"/>
    </visual>

    <inertial>
      <mass value="1e-5" />
      <origin xyz="0 0 0" rpy="0 0 0"/>
      <inertia ixx="1e-6" ixy="0" ixz="0" iyy="1e-6" iyz="0" izz="1e-6" />
    </inertial>
  </link>

  <joint name="camera_joint" type="fixed">
    <axis xyz="0 1 0" />
    <origin xyz="0 0.2 0" rpy="0 0 0"/>
    <parent link="head"/>
    <child link="camera_link"/>
  </joint>
  
  <transmission name="tran3">
    <type>transmission_interface/SimpleTransmission</type>
    <joint name="neck_head"/>
    <actuator name="motor3">
      <hardwareInterface>EffortJointInterface</hardwareInterface>
      <mechanicalReduction>1</mechanicalReduction>
    </actuator>
  </transmission>
    
  <transmission name="tran4">
    <type>transmission_interface/SimpleTransmission</type>
    <joint name="baselink_neck"/>
    <actuator name="motor4">
      <hardwareInterface>EffortJointInterface</hardwareInterface>
      <mechanicalReduction>1</mechanicalReduction>
    </actuator>
  </transmission>
  
  <transmission name="tran2">
    <type>transmission_interface/SimpleTransmission</type>
    <joint name="left_front_wheel_joint"/>
    <actuator name="motor2">
      <hardwareInterface>EffortJointInterface</hardwareInterface>
      <mechanicalReduction>1</mechanicalReduction>
    </actuator>
  </transmission>
  
  <transmission name="tran1">
    <type>transmission_interface/SimpleTransmission</type>
    <joint name="right_front_wheel_joint"/>
    <actuator name="motor1">
      <hardwareInterface>EffortJointInterface</hardwareInterface>
      <mechanicalReduction>1</mechanicalReduction>
    </actuator>
  </transmission>

</robot>
