<robot
  name="body_description">
  
    <link name="world"/>

  <joint name="fixed" type="fixed">
    <parent link="world"/>
    <child link="Body"/>
  </joint>
  
  <link
    name="Body">
    <inertial>
      <origin
        xyz="-0.042987 2.2314E-17 0.10015"
        rpy="0 0 0" />
      <mass
        value="55.244" />
      <inertia
        ixx="2.6337"
        ixy="-1.0963E-18"
        ixz="-0.00047938"
        iyy="1.8437"
        iyz="-2.401E-16"
        izz="1.1584" />
    </inertial>
    <visual>
      <origin
        xyz="0 0 0"
        rpy="0 0 0" />
      <geometry>
        <mesh
          filename="package://body_description/meshes/Body.STL" />
      </geometry>
      <material
        name="">
        <color
          rgba="0.29412 0.29412 0.29412 1" />
      </material>
    </visual>
    <collision>
      <origin
        xyz="0 0 0"
        rpy="0 0 0" />
      <geometry>
        <mesh
          filename="package://body_description/meshes/Body.STL" />
      </geometry>
    </collision>
  </link>
  <link
    name="HipR">
    <inertial>
      <origin
        xyz="-0.0010549 -0.050129 0"
        rpy="0 0 0" />
      <mass
        value="3.8278" />
      <inertia
        ixx="0.0078315"
        ixy="1.5413E-05"
        ixz="8.4233E-20"
        iyy="0.004333"
        iyz="-1.0641E-19"
        izz="0.0091464" />
    </inertial>
    <visual>
      <origin
        xyz="0 0 0"
        rpy="0 0 0" />
      <geometry>
        <mesh
          filename="package://body_description/meshes/HipR.STL" />
      </geometry>
      <material
        name="">
        <color
          rgba="0.52941 0.54902 0.54902 1" />
      </material>
    </visual>
    <collision>
      <origin
        xyz="0 0 0"
        rpy="0 0 0" />
      <geometry>
        <mesh
          filename="package://body_description/meshes/HipR.STL" />
      </geometry>
    </collision>
  </link>
  <joint
    name="HipR"
    type="revolute">
    <origin
      xyz="-0.042951 -0.18 -0.20979"
      rpy="1.5708 0 0" />
    <parent
      link="Body" />
    <child
      link="HipR" />
    <axis
      xyz="0 -1 0" />
    <limit
      effort="0"
      velocity="0" />
  </joint>
  <link
    name="thighR">
    <inertial>
      <origin
        xyz="1.1796E-16 -0.2214 0.0025"
        rpy="0 0 0" />
      <mass
        value="19.016" />
      <inertia
        ixx="0.21742"
        ixy="1.1983E-17"
        ixz="-2.4324E-19"
        iyy="0.026036"
        iyz="1.6044E-19"
        izz="0.21082" />
    </inertial>
    <visual>
      <origin
        xyz="0 0 0"
        rpy="0 0 0" />
      <geometry>
        <mesh
          filename="package://body_description/meshes/thighR.STL" />
      </geometry>
      <material
        name="">
        <color
          rgba="0.64706 0.61961 0.58824 1" />
      </material>
    </visual>
    <collision>
      <origin
        xyz="0 0 0"
        rpy="0 0 0" />
      <geometry>
        <mesh
          filename="package://body_description/meshes/thighR.STL" />
      </geometry>
    </collision>
  </link>
  <joint
    name="KneeUpR"
    type="revolute">
    <origin
      xyz="-0.0011675 -0.068 0"
      rpy="0 0 0" />
    <parent
      link="HipR" />
    <child
      link="thighR" />
    <axis
      xyz="0 0 -1" />
    <limit
      effort="0"
      velocity="0" />
  </joint>
  <link
    name="ShankR">
    <inertial>
      <origin
        xyz="1.1796E-16 -0.2214 0.0025"
        rpy="0 0 0" />
      <mass
        value="19.016" />
      <inertia
        ixx="0.21742"
        ixy="1.0337E-17"
        ixz="-5.9544E-19"
        iyy="0.026036"
        iyz="-9.9194E-19"
        izz="0.21082" />
    </inertial>
    <visual>
      <origin
        xyz="0 0 0"
        rpy="0 0 0" />
      <geometry>
        <mesh
          filename="package://body_description/meshes/ShankR.STL" />
      </geometry>
      <material
        name="">
        <color
          rgba="0.64706 0.61961 0.58824 1" />
      </material>
    </visual>
    <collision>
      <origin
        xyz="0 0 0"
        rpy="0 0 0" />
      <geometry>
        <mesh
          filename="package://body_description/meshes/ShankR.STL" />
      </geometry>
    </collision>
  </link>
  <joint
    name="kneeR"
    type="revolute">
    <origin
      xyz="0 -0.37184 0"
      rpy="0 0 0" />
    <parent
      link="thighR" />
    <child
      link="ShankR" />
    <axis
      xyz="0 0 -1" />
    <limit
      effort="0"
      velocity="0" />
  </joint>
  <link
    name="FootR">
    <inertial>
      <origin
        xyz="0.032361 -0.089245 0.00015647"
        rpy="0 0 0" />
      <mass
        value="1.2008" />
      <inertia
        ixx="0.0024541"
        ixy="-0.00043715"
        ixz="-1.6235E-18"
        iyy="0.0077791"
        iyz="1.1095E-19"
        izz="0.0067244" />
    </inertial>
    <visual>
      <origin
        xyz="0 0 0"
        rpy="0 0 0" />
      <geometry>
        <mesh
          filename="package://body_description/meshes/FootR.STL" />
      </geometry>
      <material
        name="">
        <color
          rgba="0.29412 0.29412 0.29412 1" />
      </material>
    </visual>
    <collision>
      <origin
        xyz="0 0 0"
        rpy="0 0 0" />
      <geometry>
        <mesh
          filename="package://body_description/meshes/FootR.STL" />
      </geometry>
    </collision>
  </link>
  <joint
    name="ankleR"
    type="revolute">
    <origin
      xyz="0 -0.37184 0"
      rpy="0 0 0" />
    <parent
      link="ShankR" />
    <child
      link="FootR" />
    <axis
      xyz="0 0 -1" />
    <limit
      effort="0"
      velocity="0" />
  </joint>
  <link
    name="HipL">
    <inertial>
      <origin
        xyz="-0.00105485496641898 -0.0501285703611945 0"
        rpy="0 0 0" />
      <mass
        value="3.82779005893202" />
      <inertia
        ixx="0.00783153648623665"
        ixy="1.54131512206649E-05"
        ixz="5.74060106289353E-20"
        iyy="0.00433298689106094"
        iyz="5.82735608219907E-19"
        izz="0.00914636479865238" />
    </inertial>
    <visual>
      <origin
        xyz="0 0 0"
        rpy="0 0 0" />
      <geometry>
        <mesh
          filename="package://body_description/meshes/HipL.STL" />
      </geometry>
      <material
        name="">
        <color
          rgba="0.529411764705882 0.549019607843137 0.549019607843137 1" />
      </material>
    </visual>
    <collision>
      <origin
        xyz="0 0 0"
        rpy="0 0 0" />
      <geometry>
        <mesh
          filename="package://body_description/meshes/HipL.STL" />
      </geometry>
    </collision>
  </link>
  <joint
    name="HipL"
    type="revolute">
    <origin
      xyz="-0.042951 0.18 -0.20979"
      rpy="1.5708 0 0" />
    <parent
      link="Body" />
    <child
      link="HipL" />
    <axis
      xyz="0 -1 0" />
    <limit
      effort="0"
      velocity="0" />
  </joint>
  <link
    name="thighL">
    <inertial>
      <origin
        xyz="3.01841884819964E-15 -0.221395157994845 -0.00250000000000136"
        rpy="0 0 0" />
      <mass
        value="19.0156216032149" />
      <inertia
        ixx="0.217420760192642"
        ixy="1.10242929753221E-17"
        ixz="-3.4688625575058E-19"
        iyy="0.0260364120306275"
        iyz="2.86382149782102E-19"
        izz="0.210824286411334" />
    </inertial>
    <visual>
      <origin
        xyz="0 0 0"
        rpy="0 0 0" />
      <geometry>
        <mesh
          filename="package://body_description/meshes/thighL.STL" />
      </geometry>
      <material
        name="">
        <color
          rgba="0.647058823529412 0.619607843137255 0.588235294117647 1" />
      </material>
    </visual>
    <collision>
      <origin
        xyz="0 0 0"
        rpy="0 0 0" />
      <geometry>
        <mesh
          filename="package://body_description/meshes/thighL.STL" />
      </geometry>
    </collision>
  </link>
  <joint
    name="KneeUpL"
    type="revolute">
    <origin
      xyz="-0.0011675 -0.068 0"
      rpy="0 0 0" />
    <parent
      link="HipL" />
    <child
      link="thighL" />
    <axis
      xyz="0 0 -1" />
    <limit
      effort="0"
      velocity="0" />
  </joint>
  <link
    name="ShankL">
    <inertial>
      <origin
        xyz="3.05311331771918E-16 -0.221395157994845 -0.00250000000000133"
        rpy="0 0 0" />
      <mass
        value="19.0156216032149" />
      <inertia
        ixx="0.217420760192642"
        ixy="9.39166378737544E-18"
        ixz="-7.06105859011909E-19"
        iyy="0.0260364120306275"
        iyz="-9.77948611685313E-19"
        izz="0.210824286411334" />
    </inertial>
    <visual>
      <origin
        xyz="0 0 0"
        rpy="0 0 0" />
      <geometry>
        <mesh
          filename="package://body_description/meshes/ShankL.STL" />
      </geometry>
      <material
        name="">
        <color
          rgba="0.647058823529412 0.619607843137255 0.588235294117647 1" />
      </material>
    </visual>
    <collision>
      <origin
        xyz="0 0 0"
        rpy="0 0 0" />
      <geometry>
        <mesh
          filename="package://body_description/meshes/ShankL.STL" />
      </geometry>
    </collision>
  </link>
  <joint
    name="KneeL"
    type="revolute">
    <origin
      xyz="0 -0.37184 0"
      rpy="0 0 0" />
    <parent
      link="thighL" />
    <child
      link="ShankL" />
    <axis
      xyz="0 0 -1" />
    <limit
      effort="0"
      velocity="0" />
  </joint>
  <link
    name="FootL">
    <inertial>
      <origin
        xyz="0.0323611465054027 -0.0892454683551247 -0.000156474999457618"
        rpy="0 0 0" />
      <mass
        value="1.20075196173202" />
      <inertia
        ixx="0.00245406375940147"
        ixy="-0.000437151587591721"
        ixz="-1.61338472831165E-18"
        iyy="0.00777905779344629"
        iyz="1.34502298658465E-19"
        izz="0.00672436092520249" />
    </inertial>
    <visual>
      <origin
        xyz="0 0 0"
        rpy="0 0 0" />
      <geometry>
        <mesh
          filename="package://body_description/meshes/FootL.STL" />
      </geometry>
      <material
        name="">
        <color
          rgba="0.294117647058824 0.294117647058824 0.294117647058824 1" />
      </material>
    </visual>
    <collision>
      <origin
        xyz="0 0 0"
        rpy="0 0 0" />
      <geometry>
        <mesh
          filename="package://body_description/meshes/FootL.STL" />
      </geometry>
    </collision>
  </link>
  <joint
    name="ankleL"
    type="revolute">
    <origin
      xyz="0 -0.37184 0"
      rpy="0 0 0" />
    <parent
      link="ShankL" />
    <child
      link="FootL" />
    <axis
      xyz="0 0 -1" />
    <limit
      effort="0"
      velocity="0" />
  </joint>
</robot>
