<?xml version="1.0" ?>
  <robot name='robot_body'>
    <link name='Body'>
      <pose>0 0 0 0 -0 0</pose>
      <inertial>
        <pose>-0.0430338 2.51875e-17 0.0481748 0 -0 0</pose>
        <mass value="24.0443" />
        <inertia ixx="1.00752" ixy="6.08944e-17" ixz="-0.000582815" iyy="0.921605" iyz="-4.10792e-17" izz="0.246338"/>
      </inertial>
      <collision name='Body_collision'>
        <pose>0 0 0 0 -0 0</pose>
        <geometry>
          <mesh filename="package://body_description/meshes/Body.STL"/>
        </geometry>
      </collision>
      <visual name='Body_visual'>
        <pose>0 0 0 0 -0 0</pose>
        <geometry>
          <mesh filename="package://body_description/meshes/Body.STL"/>
        </geometry>
      </visual>
      <velocity_decay>
        <linear>0</linear>
        <angular>0</angular>
      </velocity_decay>
    </link>
    <link name='HipL'>
      <pose>-0.0429511 0.18 -0.209794 1.5708 -0 0</pose>
      <inertial>
        <pose>-0.00100254 -0.0268953 2.77556e-17 0 -0 0</pose>
        <mass value="0.335132" />
        <inertia ixx="0.000287366" ixy="6.91329e-07" ixz="-3.56249e-20" iyy="0.000424745" iyz="9.2117e-22" izz="0.000335542"/>
      </inertial>
      <collision name='HipL_collision'>
        <pose>0 0 0 0 -0 0</pose>
        <geometry>
          <mesh filename="package://body_description/meshes/HipL.STL"/>
        </geometry>
      </collision>
      <visual name='HipL_visual'>
        <pose>0 0 0 0 -0 0</pose>
        <geometry>
          <mesh filename="package://body_description/meshes/HipL.STL"/>
        </geometry>
      </visual>
      <velocity_decay>
        <linear>0</linear>
        <angular>0</angular>
      </velocity_decay>
    </link>
    <joint name='Hip_L_x' type='revolute'>
      <child>HipL</child>
      <parent>Body</parent>
      <limit effort="30" velocity="1.0">
          <lower>-1e+16</lower>
          <upper>1e+16</upper>
        </limit>
      <axis>
        <xyz>0 3.61121e-15 -1</xyz>
        <dynamics/>
      </axis>
    </joint>
    <link name='thighL'>
      <pose>-0.0441186 0.18 -0.277794 1.5708 -0 0</pose>
      <inertial>
        <pose>-0.0415961 -0.181209 -0.015 0 -0 0</pose>
        <mass value="1.64773" />
        <inertia ixx="0.0229938" ixy="0.00501233" ixz="9.09401e-20" iyy="0.00230868" iyz="-1.42459e-20" izz="0.0246159"/>
      </inertial>
      <collision name='thighL_collision'>
        <pose>0 0 0 0 -0 0</pose>
        <geometry>
          <mesh filename="package://body_description/meshes/thighL.STL"/>
        </geometry>
      </collision>
      <visual name='thighL_visual'>
        <pose>0 0 0 0 -0 0</pose>
        <geometry>
          <mesh filename="package://body_description/meshes/thighL.STL"/>
        </geometry>
      </visual>
      <velocity_decay>
        <linear>0</linear>
        <angular>0</angular>
      </velocity_decay>
    </link>
    <joint name='kneeL' type='revolute'>
      <child>thighL</child>
      <parent>HipL</parent>
        <limit effort="30" velocity="1.0">
          <lower>-1e+16</lower>
          <upper>1e+16</upper>
        </limit>
      <axis>
        <xyz>0 1 3.61121e-15</xyz>
        <dynamics/>
      </axis>
    </joint>
    <link name='shankL'>
      <pose>-0.0441186 0.18 -0.649637 1.5708 -0 0</pose>
      <inertial>
        <pose>-0.205108 -0.130943 -0.015 0 -0 0</pose>
        <mass value="1.64773" />
        <inertia ixx="0.0142604" ixy="0.0113799" ixz="-9.6503e-20" iyy="0.011042" iyz="-8.87327e-20" izz="0.0246159"/>
      </inertial>
      <collision name='shankL_collision'>
        <pose>0 0 0 0 -0 0</pose>
        <geometry>
          <mesh filename="package://body_description/meshes/shankL.STL"/>
        </geometry>
      </collision>
      <visual name='shankL_visual'>
        <pose>0 0 0 0 -0 0</pose>
        <geometry>
          <mesh filename="package://body_description/meshes/shankL.STL"/>
        </geometry>
      </visual>
      <velocity_decay>
        <linear>0</linear>
        <angular>0</angular>
      </velocity_decay>
    </link>
    <joint name='ankle' type='revolute'>
      <child>shankL</child>
      <parent>thighL</parent>
        <limit effort="30" velocity="1.0">
          <lower>-1e+16</lower>
          <upper>1e+16</upper>
        </limit>
      <axis>
        <xyz>0 1 3.61121e-15</xyz>
        <dynamics/>
      </axis>
    </joint>
    <link name='footL'>
      <pose>-0.0441186 0.18 -1.02148 1.5708 -0 0</pose>
      <inertial>
        <pose>-0.29328 0.0496127 -0.02 0 -0 0</pose>
        <mass value="1.13129" />
        <inertia ixx="0.00193853" ixy="-0.000384336" ixz="-1.69779e-18" iyy="0.00721765" iyz="1.21409e-19" izz="0.0065025"/>
      </inertial>
      <collision name='footL_collision'>
        <pose>0 0 0 0 -0 0</pose>
        <geometry>
          <mesh filename="package://body_description/meshes/footL.STL"/>
        </geometry>
      </collision>
      <visual name='footL_visual'>
        <pose>0 0 0 0 -0 0</pose>
        <geometry>
          <mesh filename="package://body_description/meshes/footL.STL"/>
        </geometry>
      </visual>
      <velocity_decay>
        <linear>0</linear>
        <angular>0</angular>
      </velocity_decay>
    </link>
    <joint name='ankleL' type='revolute'>
      <child>footL</child>
      <parent>shankL</parent>
        <limit effort="30" velocity="1.0">
          <lower>-1e+16</lower>
          <upper>1e+16</upper>
        </limit>
      <axis>
        <xyz>0 1 3.61121e-15</xyz>
        <dynamics/>
      </axis>
    </joint>
    <link name='HipR'>
      <pose>-0.0429511 -0.18 -0.209794 1.5708 -0 0</pose>
      <inertial>
        <pose>-0.00100254 -0.0268953 0 0 -0 0</pose>
        <mass value="0.335132" />
        <inertia ixx="0.000287366" ixy="6.91329e-07" ixz="9.45841e-21" iyy="0.000424745" iyz="-4.20604e-21" izz="0.000335542"/>
      </inertial>
      <collision name='HipR_collision'>
        <pose>0 0 0 0 -0 0</pose>
        <geometry>
          <mesh filename="package://body_description/meshes/HipR.STL"/>
        </geometry>
      </collision>
      <visual name='HipR_visual'>
        <pose>0 0 0 0 -0 0</pose>
        <geometry>
          <mesh filename="package://body_description/meshes/HipR.STL"/>
        </geometry>
      </visual>
      <velocity_decay>
        <linear>0</linear>
        <angular>0</angular>
      </velocity_decay>
    </link>
    <joint name='hipr' type='revolute'>
      <child>HipR</child>
      <parent>Body</parent>
        <limit effort="30" velocity="1.0">
          <lower>-1e+16</lower>
          <upper>1e+16</upper>
        </limit>
      <axis>
        <xyz>0 3.61121e-15 -1</xyz>
        <dynamics/>
      </axis>
    </joint>
    <link name='Hip_thighR'>
      <pose>-0.0441186 -0.18 -0.277794 1.5708 -0 0</pose>
      <inertial>
        <pose>0.13476 -0.128088 0.015 0 -0 0</pose>
        <mass value="1.64773" />
        <inertia ixx="0.0120681" ixy="-0.0114783" ixz="1.92853e-19" iyy="0.0132343" iyz="-2.44425e-19" izz="0.0246159"/>
      </inertial>
      <collision name='Hip_thighR_collision'>
        <pose>0 0 0 0 -0 0</pose>
        <geometry>
          <mesh filename="package://body_description/meshes/Hip_thighR.STL"/>
        </geometry>
      </collision>
      <visual name='Hip_thighR_visual'>
        <pose>0 0 0 0 -0 0</pose>
        <geometry>
          <mesh filename="package://body_description/meshes/Hip_thighR.STL"/>
        </geometry>
      </visual>
      <velocity_decay>
        <linear>0</linear>
        <angular>0</angular>
      </velocity_decay>
    </link>
    <joint name='HipR_x' type='revolute'>
      <child>Hip_thighR</child>
      <parent>HipR</parent>
        <limit effort="30" velocity="1.0">
          <lower>-1e+16</lower>
          <upper>1e+16</upper>
        </limit>
      <axis>
        <xyz>0 1 3.61121e-15</xyz>
        <dynamics/>
      </axis>
    </joint>
    <link name='ShankR'>
      <pose>-0.0441186 -0.18 -0.649637 1.5708 -0 0</pose>
      <inertial>
        <pose>0.26952 -0.0702546 0.015 0 -0 0</pose>
        <mass value="1.64773" />
        <inertia ixx="0.0241443" ixy="-1.24209e-19" ixz="4.10971e-21" iyy="0.00115811" iyz="-1.36586e-19" izz="0.0246159"/>
      </inertial>
      <collision name='ShankR_collision'>
        <pose>0 0 0 0 -0 0</pose>
        <geometry>
          <mesh filename="package://body_description/meshes/ShankR.STL"/>
        </geometry>
      </collision>
      <visual name='ShankR_visual'>
        <pose>0 0 0 0 -0 0</pose>
        <geometry>
          <mesh filename="package://body_description/meshes/ShankR.STL"/>
        </geometry>
      </visual>
      <velocity_decay>
        <linear>0</linear>
        <angular>0</angular>
      </velocity_decay>
    </link>
    <joint name='knee' type='revolute'>
      <child>ShankR</child>
      <parent>Hip_thighR</parent>
        <limit effort="30" velocity="1.0">
          <lower>-1e+16</lower>
          <upper>1e+16</upper>
        </limit>
      <axis>
        <xyz>0 1 3.61121e-15</xyz>
        <dynamics/>
      </axis>
    </joint>
    <link name='FootR'>
      <pose>-0.0441186 -0.18 -1.02148 1.5708 -0 0</pose>
      <inertial>
        <pose>0.303264 0.0647478 0.02 0 -0 0</pose>
        <mass value="1.13129" />
        <inertia ixx="0.00193853" ixy="-0.000384336" ixz="-1.69779e-18" iyy="0.00721765" iyz="1.21409e-19" izz="0.0065025"/>
      </inertial>
      <collision name='FootR_collision'>
        <pose>0 0 0 0 -0 0</pose>
        <geometry>
          <mesh filename="package://body_description/meshes/FootR.STL"/>
        </geometry>
      </collision>
      <visual name='FootR_visual'>
        <pose>0 0 0 0 -0 0</pose>
        <geometry>
          <mesh filename="package://body_description/meshes/FootR.STL"/>
        </geometry>
      </visual>
      <velocity_decay>
        <linear>0</linear>
        <angular>0</angular>
      </velocity_decay>
    </link>
    <joint name='ankleR' type='revolute'>
      <child>FootR</child>
      <parent>ShankR</parent>
        <limit effort="30" velocity="1.0">
          <lower>-1e+16</lower>
          <upper>1e+16</upper>
        </limit>
      <axis>
        <xyz>0 1 3.61121e-15</xyz>
        <dynamics/>
      </axis>
    </joint>
  </robot>
